CRITICAL - 2022-01-07 00:45:10 --> SQLSTATE[HY000] [2002] No connection could be made because the target machine actively refused it
#0 C:\xampp\htdocs\cig4\vendor\bshaffer\oauth2-server-php\src\OAuth2\Storage\Pdo.php(67): PDO->__construct('mysql:dbname=ec...', 'root', '', Array)
#1 C:\xampp\htdocs\cig4\app\Libraries\Oauth.php(19): OAuth2\Storage\Pdo->__construct(Array)
#2 C:\xampp\htdocs\cig4\app\Libraries\Oauth.php(11): App\libraries\Oauth->init()
#3 C:\xampp\htdocs\cig4\app\Controllers\user.php(14): App\libraries\Oauth->__construct()
#4 C:\xampp\htdocs\cig4\system\CodeIgniter.php(824): App\Controllers\User->login()
#5 C:\xampp\htdocs\cig4\system\CodeIgniter.php(410): CodeIgniter\CodeIgniter->runController(Object(App\Controllers\User))
#6 C:\xampp\htdocs\cig4\system\CodeIgniter.php(318): CodeIgniter\CodeIgniter->handleRequest(NULL, Object(Config\Cache), false)
#7 C:\xampp\htdocs\cig4\public\index.php(37): CodeIgniter\CodeIgniter->run()
#8 C:\xampp\htdocs\cig4\system\Commands\Server\rewrite.php(43): require_once('C:\\xampp\\htdocs...')
#9 {main}
ERROR - 2022-01-07 00:46:34 --> Error connecting to the database: No connection could be made because the target machine actively refused it
CRITICAL - 2022-01-07 00:46:34 --> Unable to connect to the database.
Main connection [MySQLi]: No connection could be made because the target machine actively refused it
#0 C:\xampp\htdocs\cig4\system\Database\BaseConnection.php(577): CodeIgniter\Database\BaseConnection->initialize()
#1 C:\xampp\htdocs\cig4\system\Database\BaseBuilder.php(1443): CodeIgniter\Database\BaseConnection->query('SELECT *\nFROM `...', Array, false)
#2 C:\xampp\htdocs\cig4\system\Model.php(210): CodeIgniter\Database\BaseBuilder->get()
#3 C:\xampp\htdocs\cig4\system\BaseModel.php(622): CodeIgniter\Model->doFirst()
#4 C:\xampp\htdocs\cig4\app\Controllers\Auth.php(78): CodeIgniter\BaseModel->first()
#5 C:\xampp\htdocs\cig4\system\CodeIgniter.php(824): App\Controllers\Auth->processlogin()
#6 C:\xampp\htdocs\cig4\system\CodeIgniter.php(410): CodeIgniter\CodeIgniter->runController(Object(App\Controllers\Auth))
#7 C:\xampp\htdocs\cig4\system\CodeIgniter.php(318): CodeIgniter\CodeIgniter->handleRequest(NULL, Object(Config\Cache), false)
#8 C:\xampp\htdocs\cig4\public\index.php(37): CodeIgniter\CodeIgniter->run()
#9 C:\xampp\htdocs\cig4\system\Commands\Server\rewrite.php(43): require_once('C:\\xampp\\htdocs...')
#10 {main}
ERROR - 2022-01-07 00:52:19 --> Error connecting to the database: No connection could be made because the target machine actively refused it
CRITICAL - 2022-01-07 00:52:19 --> Unable to connect to the database.
Main connection [MySQLi]: No connection could be made because the target machine actively refused it
#0 C:\xampp\htdocs\cig4\system\Database\BaseConnection.php(577): CodeIgniter\Database\BaseConnection->initialize()
#1 C:\xampp\htdocs\cig4\system\Database\BaseBuilder.php(1443): CodeIgniter\Database\BaseConnection->query('SELECT 1\nFROM `...', Array, false)
#2 C:\xampp\htdocs\cig4\system\Validation\Rules.php(161): CodeIgniter\Database\BaseBuilder->get()
#3 C:\xampp\htdocs\cig4\system\Validation\Validation.php(277): CodeIgniter\Validation\Rules->is_unique('abel@icloud.com', 'email', Array, NULL)
#4 C:\xampp\htdocs\cig4\system\Validation\Validation.php(151): CodeIgniter\Validation\Validation->processRules('email', 'email', 'abel@icloud.com', Array, Array)
#5 C:\xampp\htdocs\cig4\system\Controller.php(160): CodeIgniter\Validation\Validation->run()
#6 C:\xampp\htdocs\cig4\app\Controllers\Auth.php(22): CodeIgniter\Controller->validate(Array)
#7 C:\xampp\htdocs\cig4\system\CodeIgniter.php(824): App\Controllers\Auth->processregister()
#8 C:\xampp\htdocs\cig4\system\CodeIgniter.php(410): CodeIgniter\CodeIgniter->runController(Object(App\Controllers\Auth))
#9 C:\xampp\htdocs\cig4\system\CodeIgniter.php(318): CodeIgniter\CodeIgniter->handleRequest(NULL, Object(Config\Cache), false)
#10 C:\xampp\htdocs\cig4\public\index.php(37): CodeIgniter\CodeIgniter->run()
#11 C:\xampp\htdocs\cig4\system\Commands\Server\rewrite.php(43): require_once('C:\\xampp\\htdocs...')
#12 {main}
ERROR - 2022-01-07 00:55:37 --> Error connecting to the database: No connection could be made because the target machine actively refused it
CRITICAL - 2022-01-07 00:55:37 --> Unable to connect to the database.
Main connection [MySQLi]: No connection could be made because the target machine actively refused it
#0 C:\xampp\htdocs\cig4\system\Database\BaseConnection.php(577): CodeIgniter\Database\BaseConnection->initialize()
#1 C:\xampp\htdocs\cig4\system\Database\BaseBuilder.php(1443): CodeIgniter\Database\BaseConnection->query('SELECT 1\nFROM `...', Array, false)
#2 C:\xampp\htdocs\cig4\system\Validation\Rules.php(161): CodeIgniter\Database\BaseBuilder->get()
#3 C:\xampp\htdocs\cig4\system\Validation\Validation.php(277): CodeIgniter\Validation\Rules->is_unique('abel@icloud.com', 'email', Array, NULL)
#4 C:\xampp\htdocs\cig4\system\Validation\Validation.php(151): CodeIgniter\Validation\Validation->processRules('email', 'email', 'abel@icloud.com', Array, Array)
#5 C:\xampp\htdocs\cig4\system\Controller.php(160): CodeIgniter\Validation\Validation->run()
#6 C:\xampp\htdocs\cig4\app\Controllers\Auth.php(22): CodeIgniter\Controller->validate(Array)
#7 C:\xampp\htdocs\cig4\system\CodeIgniter.php(824): App\Controllers\Auth->processregister()
#8 C:\xampp\htdocs\cig4\system\CodeIgniter.php(410): CodeIgniter\CodeIgniter->runController(Object(App\Controllers\Auth))
#9 C:\xampp\htdocs\cig4\system\CodeIgniter.php(318): CodeIgniter\CodeIgniter->handleRequest(NULL, Object(Config\Cache), false)
#10 C:\xampp\htdocs\cig4\public\index.php(37): CodeIgniter\CodeIgniter->run()
#11 C:\xampp\htdocs\cig4\system\Commands\Server\rewrite.php(43): require_once('C:\\xampp\\htdocs...')
#12 {main}
ERROR - 2022-01-07 00:59:16 --> Error connecting to the database: No connection could be made because the target machine actively refused it
CRITICAL - 2022-01-07 00:59:16 --> Unable to connect to the database.
Main connection [MySQLi]: No connection could be made because the target machine actively refused it
#0 C:\xampp\htdocs\cig4\system\Database\BaseConnection.php(577): CodeIgniter\Database\BaseConnection->initialize()
#1 C:\xampp\htdocs\cig4\system\Database\BaseBuilder.php(1443): CodeIgniter\Database\BaseConnection->query('SELECT 1\nFROM `...', Array, false)
#2 C:\xampp\htdocs\cig4\system\Validation\Rules.php(161): CodeIgniter\Database\BaseBuilder->get()
#3 C:\xampp\htdocs\cig4\system\Validation\Validation.php(277): CodeIgniter\Validation\Rules->is_unique('abel@icloud.com', 'email', Array, NULL)
#4 C:\xampp\htdocs\cig4\system\Validation\Validation.php(151): CodeIgniter\Validation\Validation->processRules('email', 'email', 'abel@icloud.com', Array, Array)
#5 C:\xampp\htdocs\cig4\system\Controller.php(160): CodeIgniter\Validation\Validation->run()
#6 C:\xampp\htdocs\cig4\app\Controllers\Auth.php(22): CodeIgniter\Controller->validate(Array)
#7 C:\xampp\htdocs\cig4\system\CodeIgniter.php(824): App\Controllers\Auth->processregister()
#8 C:\xampp\htdocs\cig4\system\CodeIgniter.php(410): CodeIgniter\CodeIgniter->runController(Object(App\Controllers\Auth))
#9 C:\xampp\htdocs\cig4\system\CodeIgniter.php(318): CodeIgniter\CodeIgniter->handleRequest(NULL, Object(Config\Cache), false)
#10 C:\xampp\htdocs\cig4\public\index.php(37): CodeIgniter\CodeIgniter->run()
#11 C:\xampp\htdocs\cig4\system\Commands\Server\rewrite.php(43): require_once('C:\\xampp\\htdocs...')
#12 {main}
ERROR - 2022-01-07 01:03:07 --> Error connecting to the database: No connection could be made because the target machine actively refused it
CRITICAL - 2022-01-07 01:03:07 --> Unable to connect to the database.
Main connection [MySQLi]: No connection could be made because the target machine actively refused it
#0 C:\xampp\htdocs\cig4\system\Database\BaseConnection.php(577): CodeIgniter\Database\BaseConnection->initialize()
#1 C:\xampp\htdocs\cig4\system\Database\BaseBuilder.php(1443): CodeIgniter\Database\BaseConnection->query('SELECT 1\nFROM `...', Array, false)
#2 C:\xampp\htdocs\cig4\system\Validation\Rules.php(161): CodeIgniter\Database\BaseBuilder->get()
#3 C:\xampp\htdocs\cig4\system\Validation\Validation.php(277): CodeIgniter\Validation\Rules->is_unique('abel@icloud.com', 'email', Array, NULL)
#4 C:\xampp\htdocs\cig4\system\Validation\Validation.php(151): CodeIgniter\Validation\Validation->processRules('email', 'email', 'abel@icloud.com', Array, Array)
#5 C:\xampp\htdocs\cig4\system\Controller.php(160): CodeIgniter\Validation\Validation->run()
#6 C:\xampp\htdocs\cig4\app\Controllers\Auth.php(22): CodeIgniter\Controller->validate(Array)
#7 C:\xampp\htdocs\cig4\system\CodeIgniter.php(824): App\Controllers\Auth->processregister()
#8 C:\xampp\htdocs\cig4\system\CodeIgniter.php(410): CodeIgniter\CodeIgniter->runController(Object(App\Controllers\Auth))
#9 C:\xampp\htdocs\cig4\system\CodeIgniter.php(318): CodeIgniter\CodeIgniter->handleRequest(NULL, Object(Config\Cache), false)
#10 C:\xampp\htdocs\cig4\public\index.php(37): CodeIgniter\CodeIgniter->run()
#11 C:\xampp\htdocs\cig4\system\Commands\Server\rewrite.php(43): require_once('C:\\xampp\\htdocs...')
#12 {main}
ERROR - 2022-01-07 01:09:06 --> Error connecting to the database: No connection could be made because the target machine actively refused it
CRITICAL - 2022-01-07 01:09:06 --> Unable to connect to the database.
Main connection [MySQLi]: No connection could be made because the target machine actively refused it
#0 C:\xampp\htdocs\cig4\system\Database\BaseConnection.php(577): CodeIgniter\Database\BaseConnection->initialize()
#1 C:\xampp\htdocs\cig4\system\Database\BaseBuilder.php(1443): CodeIgniter\Database\BaseConnection->query('SELECT *\nFROM `...', Array, false)
#2 C:\xampp\htdocs\cig4\system\Model.php(210): CodeIgniter\Database\BaseBuilder->get()
#3 C:\xampp\htdocs\cig4\system\BaseModel.php(622): CodeIgniter\Model->doFirst()
#4 C:\xampp\htdocs\cig4\app\Controllers\Auth.php(78): CodeIgniter\BaseModel->first()
#5 C:\xampp\htdocs\cig4\system\CodeIgniter.php(824): App\Controllers\Auth->processlogin()
#6 C:\xampp\htdocs\cig4\system\CodeIgniter.php(410): CodeIgniter\CodeIgniter->runController(Object(App\Controllers\Auth))
#7 C:\xampp\htdocs\cig4\system\CodeIgniter.php(318): CodeIgniter\CodeIgniter->handleRequest(NULL, Object(Config\Cache), false)
#8 C:\xampp\htdocs\cig4\public\index.php(37): CodeIgniter\CodeIgniter->run()
#9 C:\xampp\htdocs\cig4\system\Commands\Server\rewrite.php(43): require_once('C:\\xampp\\htdocs...')
#10 {main}
ERROR - 2022-01-07 01:33:18 --> Table 'ecommerce.tbl_users' doesn't exist in engine
CRITICAL - 2022-01-07 01:33:18 --> Table 'ecommerce.tbl_users' doesn't exist in engine
#0 C:\xampp\htdocs\cig4\system\Database\MySQLi\Connection.php(292): mysqli->query('SELECT 1\nFROM `...', 0)
#1 C:\xampp\htdocs\cig4\system\Database\BaseConnection.php(670): CodeIgniter\Database\MySQLi\Connection->execute('SELECT 1\nFROM `...')
#2 C:\xampp\htdocs\cig4\system\Database\BaseConnection.php(598): CodeIgniter\Database\BaseConnection->simpleQuery('SELECT 1\nFROM `...')
#3 C:\xampp\htdocs\cig4\system\Database\BaseBuilder.php(1443): CodeIgniter\Database\BaseConnection->query('SELECT 1\nFROM `...', Array, false)
#4 C:\xampp\htdocs\cig4\system\Validation\Rules.php(161): CodeIgniter\Database\BaseBuilder->get()
#5 C:\xampp\htdocs\cig4\system\Validation\Validation.php(277): CodeIgniter\Validation\Rules->is_unique('abel@icloud.com', 'email', Array, NULL)
#6 C:\xampp\htdocs\cig4\system\Validation\Validation.php(151): CodeIgniter\Validation\Validation->processRules('email', 'email', 'abel@icloud.com', Array, Array)
#7 C:\xampp\htdocs\cig4\system\Controller.php(160): CodeIgniter\Validation\Validation->run()
#8 C:\xampp\htdocs\cig4\app\Controllers\Auth.php(22): CodeIgniter\Controller->validate(Array)
#9 C:\xampp\htdocs\cig4\system\CodeIgniter.php(824): App\Controllers\Auth->processregister()
#10 C:\xampp\htdocs\cig4\system\CodeIgniter.php(410): CodeIgniter\CodeIgniter->runController(Object(App\Controllers\Auth))
#11 C:\xampp\htdocs\cig4\system\CodeIgniter.php(318): CodeIgniter\CodeIgniter->handleRequest(NULL, Object(Config\Cache), false)
#12 C:\xampp\htdocs\cig4\public\index.php(37): CodeIgniter\CodeIgniter->run()
#13 C:\xampp\htdocs\cig4\system\Commands\Server\rewrite.php(43): require_once('C:\\xampp\\htdocs...')
#14 {main}
ERROR - 2022-01-07 01:35:30 --> Table 'ecommerce.tbl_users' doesn't exist in engine
CRITICAL - 2022-01-07 01:35:30 --> Table 'ecommerce.tbl_users' doesn't exist in engine
#0 C:\xampp\htdocs\cig4\system\Database\MySQLi\Connection.php(292): mysqli->query('SELECT 1\nFROM `...', 0)
#1 C:\xampp\htdocs\cig4\system\Database\BaseConnection.php(670): CodeIgniter\Database\MySQLi\Connection->execute('SELECT 1\nFROM `...')
#2 C:\xampp\htdocs\cig4\system\Database\BaseConnection.php(598): CodeIgniter\Database\BaseConnection->simpleQuery('SELECT 1\nFROM `...')
#3 C:\xampp\htdocs\cig4\system\Database\BaseBuilder.php(1443): CodeIgniter\Database\BaseConnection->query('SELECT 1\nFROM `...', Array, false)
#4 C:\xampp\htdocs\cig4\system\Validation\Rules.php(161): CodeIgniter\Database\BaseBuilder->get()
#5 C:\xampp\htdocs\cig4\system\Validation\Validation.php(277): CodeIgniter\Validation\Rules->is_unique('abel@icloud.com', 'email', Array, NULL)
#6 C:\xampp\htdocs\cig4\system\Validation\Validation.php(151): CodeIgniter\Validation\Validation->processRules('email', 'email', 'abel@icloud.com', Array, Array)
#7 C:\xampp\htdocs\cig4\system\Controller.php(160): CodeIgniter\Validation\Validation->run()
#8 C:\xampp\htdocs\cig4\app\Controllers\Auth.php(22): CodeIgniter\Controller->validate(Array)
#9 C:\xampp\htdocs\cig4\system\CodeIgniter.php(824): App\Controllers\Auth->processregister()
#10 C:\xampp\htdocs\cig4\system\CodeIgniter.php(410): CodeIgniter\CodeIgniter->runController(Object(App\Controllers\Auth))
#11 C:\xampp\htdocs\cig4\system\CodeIgniter.php(318): CodeIgniter\CodeIgniter->handleRequest(NULL, Object(Config\Cache), false)
#12 C:\xampp\htdocs\cig4\public\index.php(37): CodeIgniter\CodeIgniter->run()
#13 C:\xampp\htdocs\cig4\system\Commands\Server\rewrite.php(43): require_once('C:\\xampp\\htdocs...')
#14 {main}
ERROR - 2022-01-07 05:34:48 --> Unknown column 'subcategory' in 'field list'
CRITICAL - 2022-01-07 05:34:48 --> Unknown column 'subcategory' in 'field list'
#0 C:\xampp\htdocs\cig4\system\Database\MySQLi\Connection.php(292): mysqli->query('SELECT product_...', 0)
#1 C:\xampp\htdocs\cig4\system\Database\BaseConnection.php(670): CodeIgniter\Database\MySQLi\Connection->execute('SELECT product_...')
#2 C:\xampp\htdocs\cig4\system\Database\BaseConnection.php(598): CodeIgniter\Database\BaseConnection->simpleQuery('SELECT product_...')
#3 C:\xampp\htdocs\cig4\app\Views\auth\items_show.php(123): CodeIgniter\Database\BaseConnection->query('SELECT product_...')
#4 C:\xampp\htdocs\cig4\system\View\View.php(214): include('C:\\xampp\\htdocs...')
#5 C:\xampp\htdocs\cig4\system\View\View.php(217): CodeIgniter\View\View->CodeIgniter\View\{closure}()
#6 C:\xampp\htdocs\cig4\system\Common.php(1097): CodeIgniter\View\View->render('auth/items_show...', Array, true)
#7 C:\xampp\htdocs\cig4\app\Controllers\pages.php(47): view('auth/items_show...')
#8 C:\xampp\htdocs\cig4\system\CodeIgniter.php(824): App\Controllers\Pages->itemshow()
#9 C:\xampp\htdocs\cig4\system\CodeIgniter.php(410): CodeIgniter\CodeIgniter->runController(Object(App\Controllers\Pages))
#10 C:\xampp\htdocs\cig4\system\CodeIgniter.php(318): CodeIgniter\CodeIgniter->handleRequest(NULL, Object(Config\Cache), false)
#11 C:\xampp\htdocs\cig4\public\index.php(37): CodeIgniter\CodeIgniter->run()
#12 C:\xampp\htdocs\cig4\system\Commands\Server\rewrite.php(43): require_once('C:\\xampp\\htdocs...')
#13 {main}
ERROR - 2022-01-07 05:35:14 --> Unknown column 'subcategory' in 'field list'
CRITICAL - 2022-01-07 05:35:14 --> Unknown column 'subcategory' in 'field list'
#0 C:\xampp\htdocs\cig4\system\Database\MySQLi\Connection.php(292): mysqli->query('SELECT product_...', 0)
#1 C:\xampp\htdocs\cig4\system\Database\BaseConnection.php(670): CodeIgniter\Database\MySQLi\Connection->execute('SELECT product_...')
#2 C:\xampp\htdocs\cig4\system\Database\BaseConnection.php(598): CodeIgniter\Database\BaseConnection->simpleQuery('SELECT product_...')
#3 C:\xampp\htdocs\cig4\app\Views\auth\items_show.php(123): CodeIgniter\Database\BaseConnection->query('SELECT product_...')
#4 C:\xampp\htdocs\cig4\system\View\View.php(214): include('C:\\xampp\\htdocs...')
#5 C:\xampp\htdocs\cig4\system\View\View.php(217): CodeIgniter\View\View->CodeIgniter\View\{closure}()
#6 C:\xampp\htdocs\cig4\system\Common.php(1097): CodeIgniter\View\View->render('auth/items_show...', Array, true)
#7 C:\xampp\htdocs\cig4\app\Controllers\pages.php(47): view('auth/items_show...')
#8 C:\xampp\htdocs\cig4\system\CodeIgniter.php(824): App\Controllers\Pages->itemshow()
#9 C:\xampp\htdocs\cig4\system\CodeIgniter.php(410): CodeIgniter\CodeIgniter->runController(Object(App\Controllers\Pages))
#10 C:\xampp\htdocs\cig4\system\CodeIgniter.php(318): CodeIgniter\CodeIgniter->handleRequest(NULL, Object(Config\Cache), false)
#11 C:\xampp\htdocs\cig4\public\index.php(37): CodeIgniter\CodeIgniter->run()
#12 C:\xampp\htdocs\cig4\system\Commands\Server\rewrite.php(43): require_once('C:\\xampp\\htdocs...')
#13 {main}
CRITICAL - 2022-01-07 05:45:10 --> Uncaught TypeError: abs(): Argument #1 ($num) must be of type int|float, string given in C:\xampp\htdocs\cig4\system\Debug\Exceptions.php:293
Stack trace:
#0 C:\xampp\htdocs\cig4\system\Debug\Exceptions.php(293): abs('42S02')
#1 C:\xampp\htdocs\cig4\system\Debug\Exceptions.php(97): CodeIgniter\Debug\Exceptions->determineCodes(Object(PDOException))
#2 [internal function]: CodeIgniter\Debug\Exceptions->exceptionHandler(Object(PDOException))
#3 {main}
  thrown
#0 [internal function]: CodeIgniter\Debug\Exceptions->shutdownHandler()
#1 {main}
CRITICAL - 2022-01-07 05:46:24 --> Uncaught TypeError: abs(): Argument #1 ($num) must be of type int|float, string given in C:\xampp\htdocs\cig4\system\Debug\Exceptions.php:293
Stack trace:
#0 C:\xampp\htdocs\cig4\system\Debug\Exceptions.php(293): abs('42S02')
#1 C:\xampp\htdocs\cig4\system\Debug\Exceptions.php(97): CodeIgniter\Debug\Exceptions->determineCodes(Object(PDOException))
#2 [internal function]: CodeIgniter\Debug\Exceptions->exceptionHandler(Object(PDOException))
#3 {main}
  thrown
#0 [internal function]: CodeIgniter\Debug\Exceptions->shutdownHandler()
#1 {main}
CRITICAL - 2022-01-07 05:48:18 --> Uncaught TypeError: abs(): Argument #1 ($num) must be of type int|float, string given in C:\xampp\htdocs\cig4\system\Debug\Exceptions.php:293
Stack trace:
#0 C:\xampp\htdocs\cig4\system\Debug\Exceptions.php(293): abs('42S02')
#1 C:\xampp\htdocs\cig4\system\Debug\Exceptions.php(97): CodeIgniter\Debug\Exceptions->determineCodes(Object(PDOException))
#2 [internal function]: CodeIgniter\Debug\Exceptions->exceptionHandler(Object(PDOException))
#3 {main}
  thrown
#0 [internal function]: CodeIgniter\Debug\Exceptions->shutdownHandler()
#1 {main}
CRITICAL - 2022-01-07 05:51:07 --> Uncaught TypeError: abs(): Argument #1 ($num) must be of type int|float, string given in C:\xampp\htdocs\cig4\system\Debug\Exceptions.php:293
Stack trace:
#0 C:\xampp\htdocs\cig4\system\Debug\Exceptions.php(293): abs('42S02')
#1 C:\xampp\htdocs\cig4\system\Debug\Exceptions.php(97): CodeIgniter\Debug\Exceptions->determineCodes(Object(PDOException))
#2 [internal function]: CodeIgniter\Debug\Exceptions->exceptionHandler(Object(PDOException))
#3 {main}
  thrown
#0 [internal function]: CodeIgniter\Debug\Exceptions->shutdownHandler()
#1 {main}
CRITICAL - 2022-01-07 05:55:09 --> Object of class CodeIgniter\Router\RouteCollection could not be converted to string
#0 C:\xampp\htdocs\cig4\system\CodeIgniter.php(705): require()
#1 C:\xampp\htdocs\cig4\system\CodeIgniter.php(359): CodeIgniter\CodeIgniter->tryToRouteIt(Object(CodeIgniter\Router\RouteCollection))
#2 C:\xampp\htdocs\cig4\system\CodeIgniter.php(318): CodeIgniter\CodeIgniter->handleRequest(NULL, Object(Config\Cache), false)
#3 C:\xampp\htdocs\cig4\public\index.php(37): CodeIgniter\CodeIgniter->run()
#4 C:\xampp\htdocs\cig4\system\Commands\Server\rewrite.php(43): require_once('C:\\xampp\\htdocs...')
#5 {main}
CRITICAL - 2022-01-07 05:55:30 --> Uncaught TypeError: abs(): Argument #1 ($num) must be of type int|float, string given in C:\xampp\htdocs\cig4\system\Debug\Exceptions.php:293
Stack trace:
#0 C:\xampp\htdocs\cig4\system\Debug\Exceptions.php(293): abs('42S02')
#1 C:\xampp\htdocs\cig4\system\Debug\Exceptions.php(97): CodeIgniter\Debug\Exceptions->determineCodes(Object(PDOException))
#2 [internal function]: CodeIgniter\Debug\Exceptions->exceptionHandler(Object(PDOException))
#3 {main}
  thrown
#0 [internal function]: CodeIgniter\Debug\Exceptions->shutdownHandler()
#1 {main}
CRITICAL - 2022-01-07 05:56:04 --> Uncaught TypeError: abs(): Argument #1 ($num) must be of type int|float, string given in C:\xampp\htdocs\cig4\system\Debug\Exceptions.php:293
Stack trace:
#0 C:\xampp\htdocs\cig4\system\Debug\Exceptions.php(293): abs('42S02')
#1 C:\xampp\htdocs\cig4\system\Debug\Exceptions.php(97): CodeIgniter\Debug\Exceptions->determineCodes(Object(PDOException))
#2 [internal function]: CodeIgniter\Debug\Exceptions->exceptionHandler(Object(PDOException))
#3 {main}
  thrown
#0 [internal function]: CodeIgniter\Debug\Exceptions->shutdownHandler()
#1 {main}
CRITICAL - 2022-01-07 06:03:26 --> Uncaught TypeError: abs(): Argument #1 ($num) must be of type int|float, string given in C:\xampp\htdocs\cig4\system\Debug\Exceptions.php:293
Stack trace:
#0 C:\xampp\htdocs\cig4\system\Debug\Exceptions.php(293): abs('42S02')
#1 C:\xampp\htdocs\cig4\system\Debug\Exceptions.php(97): CodeIgniter\Debug\Exceptions->determineCodes(Object(PDOException))
#2 [internal function]: CodeIgniter\Debug\Exceptions->exceptionHandler(Object(PDOException))
#3 {main}
  thrown
#0 [internal function]: CodeIgniter\Debug\Exceptions->shutdownHandler()
#1 {main}
CRITICAL - 2022-01-07 06:03:33 --> Uncaught TypeError: abs(): Argument #1 ($num) must be of type int|float, string given in C:\xampp\htdocs\cig4\system\Debug\Exceptions.php:293
Stack trace:
#0 C:\xampp\htdocs\cig4\system\Debug\Exceptions.php(293): abs('42S02')
#1 C:\xampp\htdocs\cig4\system\Debug\Exceptions.php(97): CodeIgniter\Debug\Exceptions->determineCodes(Object(PDOException))
#2 [internal function]: CodeIgniter\Debug\Exceptions->exceptionHandler(Object(PDOException))
#3 {main}
  thrown
#0 [internal function]: CodeIgniter\Debug\Exceptions->shutdownHandler()
#1 {main}
CRITICAL - 2022-01-07 06:11:07 --> Uncaught TypeError: abs(): Argument #1 ($num) must be of type int|float, string given in C:\xampp\htdocs\cig4\system\Debug\Exceptions.php:293
Stack trace:
#0 C:\xampp\htdocs\cig4\system\Debug\Exceptions.php(293): abs('42S02')
#1 C:\xampp\htdocs\cig4\system\Debug\Exceptions.php(97): CodeIgniter\Debug\Exceptions->determineCodes(Object(PDOException))
#2 [internal function]: CodeIgniter\Debug\Exceptions->exceptionHandler(Object(PDOException))
#3 {main}
  thrown
#0 [internal function]: CodeIgniter\Debug\Exceptions->shutdownHandler()
#1 {main}
CRITICAL - 2022-01-07 06:34:01 --> Uncaught TypeError: abs(): Argument #1 ($num) must be of type int|float, string given in C:\xampp\htdocs\cig4\system\Debug\Exceptions.php:293
Stack trace:
#0 C:\xampp\htdocs\cig4\system\Debug\Exceptions.php(293): abs('42S02')
#1 C:\xampp\htdocs\cig4\system\Debug\Exceptions.php(97): CodeIgniter\Debug\Exceptions->determineCodes(Object(PDOException))
#2 [internal function]: CodeIgniter\Debug\Exceptions->exceptionHandler(Object(PDOException))
#3 {main}
  thrown
#0 [internal function]: CodeIgniter\Debug\Exceptions->shutdownHandler()
#1 {main}
CRITICAL - 2022-01-07 06:34:17 --> Uncaught TypeError: abs(): Argument #1 ($num) must be of type int|float, string given in C:\xampp\htdocs\cig4\system\Debug\Exceptions.php:293
Stack trace:
#0 C:\xampp\htdocs\cig4\system\Debug\Exceptions.php(293): abs('42S02')
#1 C:\xampp\htdocs\cig4\system\Debug\Exceptions.php(97): CodeIgniter\Debug\Exceptions->determineCodes(Object(PDOException))
#2 [internal function]: CodeIgniter\Debug\Exceptions->exceptionHandler(Object(PDOException))
#3 {main}
  thrown
#0 [internal function]: CodeIgniter\Debug\Exceptions->shutdownHandler()
#1 {main}
CRITICAL - 2022-01-07 06:36:31 --> Uncaught TypeError: abs(): Argument #1 ($num) must be of type int|float, string given in C:\xampp\htdocs\cig4\system\Debug\Exceptions.php:293
Stack trace:
#0 C:\xampp\htdocs\cig4\system\Debug\Exceptions.php(293): abs('42S02')
#1 C:\xampp\htdocs\cig4\system\Debug\Exceptions.php(97): CodeIgniter\Debug\Exceptions->determineCodes(Object(PDOException))
#2 [internal function]: CodeIgniter\Debug\Exceptions->exceptionHandler(Object(PDOException))
#3 {main}
  thrown
#0 [internal function]: CodeIgniter\Debug\Exceptions->shutdownHandler()
#1 {main}
CRITICAL - 2022-01-07 06:36:38 --> Uncaught TypeError: abs(): Argument #1 ($num) must be of type int|float, string given in C:\xampp\htdocs\cig4\system\Debug\Exceptions.php:293
Stack trace:
#0 C:\xampp\htdocs\cig4\system\Debug\Exceptions.php(293): abs('42S02')
#1 C:\xampp\htdocs\cig4\system\Debug\Exceptions.php(97): CodeIgniter\Debug\Exceptions->determineCodes(Object(PDOException))
#2 [internal function]: CodeIgniter\Debug\Exceptions->exceptionHandler(Object(PDOException))
#3 {main}
  thrown
#0 [internal function]: CodeIgniter\Debug\Exceptions->shutdownHandler()
#1 {main}
CRITICAL - 2022-01-07 06:37:01 --> Uncaught TypeError: abs(): Argument #1 ($num) must be of type int|float, string given in C:\xampp\htdocs\cig4\system\Debug\Exceptions.php:293
Stack trace:
#0 C:\xampp\htdocs\cig4\system\Debug\Exceptions.php(293): abs('42S02')
#1 C:\xampp\htdocs\cig4\system\Debug\Exceptions.php(97): CodeIgniter\Debug\Exceptions->determineCodes(Object(PDOException))
#2 [internal function]: CodeIgniter\Debug\Exceptions->exceptionHandler(Object(PDOException))
#3 {main}
  thrown
#0 [internal function]: CodeIgniter\Debug\Exceptions->shutdownHandler()
#1 {main}
CRITICAL - 2022-01-07 06:44:46 --> Uncaught TypeError: abs(): Argument #1 ($num) must be of type int|float, string given in C:\xampp\htdocs\cig4\system\Debug\Exceptions.php:293
Stack trace:
#0 C:\xampp\htdocs\cig4\system\Debug\Exceptions.php(293): abs('42S02')
#1 C:\xampp\htdocs\cig4\system\Debug\Exceptions.php(97): CodeIgniter\Debug\Exceptions->determineCodes(Object(PDOException))
#2 [internal function]: CodeIgniter\Debug\Exceptions->exceptionHandler(Object(PDOException))
#3 {main}
  thrown
#0 [internal function]: CodeIgniter\Debug\Exceptions->shutdownHandler()
#1 {main}
CRITICAL - 2022-01-07 08:07:27 --> Trying to access array offset on value of type null
#0 C:\xampp\htdocs\cig4\app\Controllers\Auth.php(79): CodeIgniter\Debug\Exceptions->errorHandler(2, 'Trying to acces...', 'C:\\xampp\\htdocs...', 79)
#1 C:\xampp\htdocs\cig4\system\CodeIgniter.php(824): App\Controllers\Auth->processlogin()
#2 C:\xampp\htdocs\cig4\system\CodeIgniter.php(410): CodeIgniter\CodeIgniter->runController(Object(App\Controllers\Auth))
#3 C:\xampp\htdocs\cig4\system\CodeIgniter.php(318): CodeIgniter\CodeIgniter->handleRequest(NULL, Object(Config\Cache), false)
#4 C:\xampp\htdocs\cig4\public\index.php(37): CodeIgniter\CodeIgniter->run()
#5 C:\xampp\htdocs\cig4\system\Commands\Server\rewrite.php(43): require_once('C:\\xampp\\htdocs...')
#6 {main}
CRITICAL - 2022-01-07 08:42:56 --> Declaration of App\Filters\OauthFilter::before(CodeIgniter\HTTP\RequestInterface $request) must be compatible with CodeIgniter\Filters\FilterInterface::before(CodeIgniter\HTTP\RequestInterface $request, $arguments = null)
#0 [internal function]: CodeIgniter\Debug\Exceptions->shutdownHandler()
#1 {main}
ERROR - 2022-01-07 10:37:26 --> Column 'added_by' cannot be null
CRITICAL - 2022-01-07 10:37:26 --> Column 'added_by' cannot be null
#0 C:\xampp\htdocs\cig4\system\Database\MySQLi\Connection.php(292): mysqli->query('INSERT INTO `tb...', 0)
#1 C:\xampp\htdocs\cig4\system\Database\BaseConnection.php(670): CodeIgniter\Database\MySQLi\Connection->execute('INSERT INTO `tb...')
#2 C:\xampp\htdocs\cig4\system\Database\BaseConnection.php(598): CodeIgniter\Database\BaseConnection->simpleQuery('INSERT INTO `tb...')
#3 C:\xampp\htdocs\cig4\system\Database\BaseBuilder.php(1759): CodeIgniter\Database\BaseConnection->query('INSERT INTO `tb...', Array, false)
#4 C:\xampp\htdocs\cig4\system\Model.php(239): CodeIgniter\Database\BaseBuilder->insert()
#5 C:\xampp\htdocs\cig4\system\BaseModel.php(738): CodeIgniter\Model->doInsert(Array)
#6 C:\xampp\htdocs\cig4\system\Model.php(620): CodeIgniter\BaseModel->insert(Array, false)
#7 C:\xampp\htdocs\cig4\system\BaseModel.php(658): CodeIgniter\Model->insert(Array, false)
#8 C:\xampp\htdocs\cig4\app\Controllers\Auth.php(333): CodeIgniter\BaseModel->save(Array)
#9 C:\xampp\htdocs\cig4\system\CodeIgniter.php(824): App\Controllers\Auth->processapi()
#10 C:\xampp\htdocs\cig4\system\CodeIgniter.php(410): CodeIgniter\CodeIgniter->runController(Object(App\Controllers\Auth))
#11 C:\xampp\htdocs\cig4\system\CodeIgniter.php(318): CodeIgniter\CodeIgniter->handleRequest(NULL, Object(Config\Cache), false)
#12 C:\xampp\htdocs\cig4\public\index.php(37): CodeIgniter\CodeIgniter->run()
#13 C:\xampp\htdocs\cig4\system\Commands\Server\rewrite.php(43): require_once('C:\\xampp\\htdocs...')
#14 {main}
ERROR - 2022-01-07 11:00:10 --> Cannot add or update a child row: a foreign key constraint fails (`stayfashionable`.`tbl_users`, CONSTRAINT `tbl_users_ibfk_1` FOREIGN KEY (`role`) REFERENCES `tbl_roles` (`role_id`) ON UPDATE CASCADE)
CRITICAL - 2022-01-07 11:00:10 --> Cannot add or update a child row: a foreign key constraint fails (`stayfashionable`.`tbl_users`, CONSTRAINT `tbl_users_ibfk_1` FOREIGN KEY (`role`) REFERENCES `tbl_roles` (`role_id`) ON UPDATE CASCADE)
#0 C:\xampp\htdocs\cig4\system\Database\MySQLi\Connection.php(292): mysqli->query('INSERT INTO `tb...', 0)
#1 C:\xampp\htdocs\cig4\system\Database\BaseConnection.php(670): CodeIgniter\Database\MySQLi\Connection->execute('INSERT INTO `tb...')
#2 C:\xampp\htdocs\cig4\system\Database\BaseConnection.php(598): CodeIgniter\Database\BaseConnection->simpleQuery('INSERT INTO `tb...')
#3 C:\xampp\htdocs\cig4\system\Database\BaseBuilder.php(1759): CodeIgniter\Database\BaseConnection->query('INSERT INTO `tb...', Array, false)
#4 C:\xampp\htdocs\cig4\system\Model.php(239): CodeIgniter\Database\BaseBuilder->insert()
#5 C:\xampp\htdocs\cig4\system\BaseModel.php(738): CodeIgniter\Model->doInsert(Array)
#6 C:\xampp\htdocs\cig4\system\Model.php(620): CodeIgniter\BaseModel->insert(Array, true)
#7 C:\xampp\htdocs\cig4\app\Controllers\user.php(55): CodeIgniter\Model->insert(Array)
#8 C:\xampp\htdocs\cig4\system\CodeIgniter.php(824): App\Controllers\User->register()
#9 C:\xampp\htdocs\cig4\system\CodeIgniter.php(410): CodeIgniter\CodeIgniter->runController(Object(App\Controllers\User))
#10 C:\xampp\htdocs\cig4\system\CodeIgniter.php(318): CodeIgniter\CodeIgniter->handleRequest(NULL, Object(Config\Cache), false)
#11 C:\xampp\htdocs\cig4\public\index.php(37): CodeIgniter\CodeIgniter->run()
#12 C:\xampp\htdocs\cig4\system\Commands\Server\rewrite.php(43): require_once('C:\\xampp\\htdocs...')
#13 {main}
CRITICAL - 2022-01-07 11:06:45 --> Class "App\Controllers\Hash" not found
#0 C:\xampp\htdocs\cig4\system\CodeIgniter.php(824): App\Controllers\User->register()
#1 C:\xampp\htdocs\cig4\system\CodeIgniter.php(410): CodeIgniter\CodeIgniter->runController(Object(App\Controllers\User))
#2 C:\xampp\htdocs\cig4\system\CodeIgniter.php(318): CodeIgniter\CodeIgniter->handleRequest(NULL, Object(Config\Cache), false)
#3 C:\xampp\htdocs\cig4\public\index.php(37): CodeIgniter\CodeIgniter->run()
#4 C:\xampp\htdocs\cig4\system\Commands\Server\rewrite.php(43): require_once('C:\\xampp\\htdocs...')
#5 {main}
CRITICAL - 2022-01-07 11:11:47 --> Undefined array key "id"
#0 C:\xampp\htdocs\cig4\app\Libraries\CustomOauthStorage.php(459): CodeIgniter\Debug\Exceptions->errorHandler(2, 'Undefined array...', 'C:\\xampp\\htdocs...', 459)
#1 C:\xampp\htdocs\cig4\app\Libraries\CustomOauthStorage.php(312): App\Libraries\CustomOauthStorage->getUser('kattie123@iclou...')
#2 C:\xampp\htdocs\cig4\vendor\bshaffer\oauth2-server-php\src\OAuth2\GrantType\UserCredentials.php(57): App\Libraries\CustomOauthStorage->checkUserCredentials('kattie123@iclou...', 'kattie100')
#3 C:\xampp\htdocs\cig4\vendor\bshaffer\oauth2-server-php\src\OAuth2\Controller\TokenController.php(175): OAuth2\GrantType\UserCredentials->validateRequest(Object(OAuth2\Request), Object(OAuth2\Response))
#4 C:\xampp\htdocs\cig4\vendor\bshaffer\oauth2-server-php\src\OAuth2\Controller\TokenController.php(87): OAuth2\Controller\TokenController->grantAccessToken(Object(OAuth2\Request), Object(OAuth2\Response))
#5 C:\xampp\htdocs\cig4\vendor\bshaffer\oauth2-server-php\src\OAuth2\Server.php(320): OAuth2\Controller\TokenController->handleTokenRequest(Object(OAuth2\Request), Object(OAuth2\Response))
#6 C:\xampp\htdocs\cig4\app\Controllers\user.php(18): OAuth2\Server->handleTokenRequest(Object(OAuth2\Request))
#7 C:\xampp\htdocs\cig4\system\CodeIgniter.php(824): App\Controllers\User->login()
#8 C:\xampp\htdocs\cig4\system\CodeIgniter.php(410): CodeIgniter\CodeIgniter->runController(Object(App\Controllers\User))
#9 C:\xampp\htdocs\cig4\system\CodeIgniter.php(318): CodeIgniter\CodeIgniter->handleRequest(NULL, Object(Config\Cache), false)
#10 C:\xampp\htdocs\cig4\public\index.php(37): CodeIgniter\CodeIgniter->run()
#11 C:\xampp\htdocs\cig4\system\Commands\Server\rewrite.php(43): require_once('C:\\xampp\\htdocs...')
#12 {main}
CRITICAL - 2022-01-07 11:28:15 --> Undefined array key "id"
#0 C:\xampp\htdocs\cig4\app\Libraries\CustomOauthStorage.php(459): CodeIgniter\Debug\Exceptions->errorHandler(2, 'Undefined array...', 'C:\\xampp\\htdocs...', 459)
#1 C:\xampp\htdocs\cig4\app\Libraries\CustomOauthStorage.php(312): App\Libraries\CustomOauthStorage->getUser('kattie123@iclou...')
#2 C:\xampp\htdocs\cig4\vendor\bshaffer\oauth2-server-php\src\OAuth2\GrantType\UserCredentials.php(57): App\Libraries\CustomOauthStorage->checkUserCredentials('kattie123@iclou...', 'kattie100')
#3 C:\xampp\htdocs\cig4\vendor\bshaffer\oauth2-server-php\src\OAuth2\Controller\TokenController.php(175): OAuth2\GrantType\UserCredentials->validateRequest(Object(OAuth2\Request), Object(OAuth2\Response))
#4 C:\xampp\htdocs\cig4\vendor\bshaffer\oauth2-server-php\src\OAuth2\Controller\TokenController.php(87): OAuth2\Controller\TokenController->grantAccessToken(Object(OAuth2\Request), Object(OAuth2\Response))
#5 C:\xampp\htdocs\cig4\vendor\bshaffer\oauth2-server-php\src\OAuth2\Server.php(320): OAuth2\Controller\TokenController->handleTokenRequest(Object(OAuth2\Request), Object(OAuth2\Response))
#6 C:\xampp\htdocs\cig4\app\Controllers\user.php(18): OAuth2\Server->handleTokenRequest(Object(OAuth2\Request))
#7 C:\xampp\htdocs\cig4\system\CodeIgniter.php(824): App\Controllers\User->login()
#8 C:\xampp\htdocs\cig4\system\CodeIgniter.php(410): CodeIgniter\CodeIgniter->runController(Object(App\Controllers\User))
#9 C:\xampp\htdocs\cig4\system\CodeIgniter.php(318): CodeIgniter\CodeIgniter->handleRequest(NULL, Object(Config\Cache), false)
#10 C:\xampp\htdocs\cig4\public\index.php(37): CodeIgniter\CodeIgniter->run()
#11 C:\xampp\htdocs\cig4\system\Commands\Server\rewrite.php(43): require_once('C:\\xampp\\htdocs...')
#12 {main}
CRITICAL - 2022-01-07 11:28:31 --> Undefined array key "id"
#0 C:\xampp\htdocs\cig4\app\Libraries\CustomOauthStorage.php(459): CodeIgniter\Debug\Exceptions->errorHandler(2, 'Undefined array...', 'C:\\xampp\\htdocs...', 459)
#1 C:\xampp\htdocs\cig4\app\Libraries\CustomOauthStorage.php(312): App\Libraries\CustomOauthStorage->getUser('kattie123@iclou...')
#2 C:\xampp\htdocs\cig4\vendor\bshaffer\oauth2-server-php\src\OAuth2\GrantType\UserCredentials.php(57): App\Libraries\CustomOauthStorage->checkUserCredentials('kattie123@iclou...', 'kattie100')
#3 C:\xampp\htdocs\cig4\vendor\bshaffer\oauth2-server-php\src\OAuth2\Controller\TokenController.php(175): OAuth2\GrantType\UserCredentials->validateRequest(Object(OAuth2\Request), Object(OAuth2\Response))
#4 C:\xampp\htdocs\cig4\vendor\bshaffer\oauth2-server-php\src\OAuth2\Controller\TokenController.php(87): OAuth2\Controller\TokenController->grantAccessToken(Object(OAuth2\Request), Object(OAuth2\Response))
#5 C:\xampp\htdocs\cig4\vendor\bshaffer\oauth2-server-php\src\OAuth2\Server.php(320): OAuth2\Controller\TokenController->handleTokenRequest(Object(OAuth2\Request), Object(OAuth2\Response))
#6 C:\xampp\htdocs\cig4\app\Controllers\user.php(18): OAuth2\Server->handleTokenRequest(Object(OAuth2\Request))
#7 C:\xampp\htdocs\cig4\system\CodeIgniter.php(824): App\Controllers\User->login()
#8 C:\xampp\htdocs\cig4\system\CodeIgniter.php(410): CodeIgniter\CodeIgniter->runController(Object(App\Controllers\User))
#9 C:\xampp\htdocs\cig4\system\CodeIgniter.php(318): CodeIgniter\CodeIgniter->handleRequest(NULL, Object(Config\Cache), false)
#10 C:\xampp\htdocs\cig4\public\index.php(37): CodeIgniter\CodeIgniter->run()
#11 C:\xampp\htdocs\cig4\system\Commands\Server\rewrite.php(43): require_once('C:\\xampp\\htdocs...')
#12 {main}
CRITICAL - 2022-01-07 11:28:44 --> Undefined array key "id"
#0 C:\xampp\htdocs\cig4\app\Libraries\CustomOauthStorage.php(459): CodeIgniter\Debug\Exceptions->errorHandler(2, 'Undefined array...', 'C:\\xampp\\htdocs...', 459)
#1 C:\xampp\htdocs\cig4\app\Libraries\CustomOauthStorage.php(312): App\Libraries\CustomOauthStorage->getUser('kattie123@iclou...')
#2 C:\xampp\htdocs\cig4\vendor\bshaffer\oauth2-server-php\src\OAuth2\GrantType\UserCredentials.php(57): App\Libraries\CustomOauthStorage->checkUserCredentials('kattie123@iclou...', 'kattie100')
#3 C:\xampp\htdocs\cig4\vendor\bshaffer\oauth2-server-php\src\OAuth2\Controller\TokenController.php(175): OAuth2\GrantType\UserCredentials->validateRequest(Object(OAuth2\Request), Object(OAuth2\Response))
#4 C:\xampp\htdocs\cig4\vendor\bshaffer\oauth2-server-php\src\OAuth2\Controller\TokenController.php(87): OAuth2\Controller\TokenController->grantAccessToken(Object(OAuth2\Request), Object(OAuth2\Response))
#5 C:\xampp\htdocs\cig4\vendor\bshaffer\oauth2-server-php\src\OAuth2\Server.php(320): OAuth2\Controller\TokenController->handleTokenRequest(Object(OAuth2\Request), Object(OAuth2\Response))
#6 C:\xampp\htdocs\cig4\app\Controllers\user.php(18): OAuth2\Server->handleTokenRequest(Object(OAuth2\Request))
#7 C:\xampp\htdocs\cig4\system\CodeIgniter.php(824): App\Controllers\User->login()
#8 C:\xampp\htdocs\cig4\system\CodeIgniter.php(410): CodeIgniter\CodeIgniter->runController(Object(App\Controllers\User))
#9 C:\xampp\htdocs\cig4\system\CodeIgniter.php(318): CodeIgniter\CodeIgniter->handleRequest(NULL, Object(Config\Cache), false)
#10 C:\xampp\htdocs\cig4\public\index.php(37): CodeIgniter\CodeIgniter->run()
#11 C:\xampp\htdocs\cig4\system\Commands\Server\rewrite.php(43): require_once('C:\\xampp\\htdocs...')
#12 {main}
CRITICAL - 2022-01-07 11:29:00 --> Undefined array key "id"
#0 C:\xampp\htdocs\cig4\app\Libraries\CustomOauthStorage.php(459): CodeIgniter\Debug\Exceptions->errorHandler(2, 'Undefined array...', 'C:\\xampp\\htdocs...', 459)
#1 C:\xampp\htdocs\cig4\app\Libraries\CustomOauthStorage.php(312): App\Libraries\CustomOauthStorage->getUser('kattie123@iclou...')
#2 C:\xampp\htdocs\cig4\vendor\bshaffer\oauth2-server-php\src\OAuth2\GrantType\UserCredentials.php(57): App\Libraries\CustomOauthStorage->checkUserCredentials('kattie123@iclou...', 'kattie100')
#3 C:\xampp\htdocs\cig4\vendor\bshaffer\oauth2-server-php\src\OAuth2\Controller\TokenController.php(175): OAuth2\GrantType\UserCredentials->validateRequest(Object(OAuth2\Request), Object(OAuth2\Response))
#4 C:\xampp\htdocs\cig4\vendor\bshaffer\oauth2-server-php\src\OAuth2\Controller\TokenController.php(87): OAuth2\Controller\TokenController->grantAccessToken(Object(OAuth2\Request), Object(OAuth2\Response))
#5 C:\xampp\htdocs\cig4\vendor\bshaffer\oauth2-server-php\src\OAuth2\Server.php(320): OAuth2\Controller\TokenController->handleTokenRequest(Object(OAuth2\Request), Object(OAuth2\Response))
#6 C:\xampp\htdocs\cig4\app\Controllers\user.php(18): OAuth2\Server->handleTokenRequest(Object(OAuth2\Request))
#7 C:\xampp\htdocs\cig4\system\CodeIgniter.php(824): App\Controllers\User->login()
#8 C:\xampp\htdocs\cig4\system\CodeIgniter.php(410): CodeIgniter\CodeIgniter->runController(Object(App\Controllers\User))
#9 C:\xampp\htdocs\cig4\system\CodeIgniter.php(318): CodeIgniter\CodeIgniter->handleRequest(NULL, Object(Config\Cache), false)
#10 C:\xampp\htdocs\cig4\public\index.php(37): CodeIgniter\CodeIgniter->run()
#11 C:\xampp\htdocs\cig4\system\Commands\Server\rewrite.php(43): require_once('C:\\xampp\\htdocs...')
#12 {main}
